...E
======================================================================
ERROR: test_saving_and_retrieving_items (lists.tests.ItemModelTest)
----------------------------------------------------------------------
Traceback (most recent call last):
  File "C:\Users\chobits\Documents\site\tdd_django\lists\tests.py", line 39, in test_saving_and_retrieving_items
    first_item.save()
AttributeError: 'Item' object has no attribute 'save'

----------------------------------------------------------------------
Ran 4 tests in 0.094s

FAILED (errors=1)
