F
======================================================================
FAIL: test_can_start_a_list_and_retrieve_it_later (__main__.NewVisitorTest)
----------------------------------------------------------------------
Traceback (most recent call last):
  File "functional_tests.py", line 18, in test_can_start_a_list_and_retrieve_it_later
    self.assertIn('To-Do', self.browser.title)
AssertionError: 'To-Do' not found in 'Welcome to Django'

----------------------------------------------------------------------
Ran 1 test in 3.452s

FAILED (failures=1)
'NoneType' object has no attribute 'path'
