E
======================================================================
ERROR: test_can_start_a_list_and_retrieve_it_later (functional_tests.tests.NewVisitorTest)
----------------------------------------------------------------------
Traceback (most recent call last):
  File "/Users/hadesshark/Documents/django_site/superlists/functional_tests/tests.py", line 52, in test_can_start_a_list_and_retrieve_it_later
    self.check_for_row_in_list_table('1: Buy peacock feathers')
  File "/Users/hadesshark/Documents/django_site/superlists/functional_tests/tests.py", line 17, in check_for_row_in_list_table
    table = self.browser.find_element_by_id('id_list_table')
  File "/usr/local/lib/python3.5/site-packages/selenium/webdriver/remote/webdriver.py", line 269, in find_element_by_id
    return self.find_element(by=By.ID, value=id_)
  File "/usr/local/lib/python3.5/site-packages/selenium/webdriver/remote/webdriver.py", line 752, in find_element
    'value': value})['value']
  File "/usr/local/lib/python3.5/site-packages/selenium/webdriver/remote/webdriver.py", line 236, in execute
    self.error_handler.check_response(response)
  File "/usr/local/lib/python3.5/site-packages/selenium/webdriver/remote/errorhandler.py", line 192, in check_response
    raise exception_class(message, screen, stacktrace)
selenium.common.exceptions.NoSuchElementException: Message: Unable to locate element: [id="id_list_table"]


----------------------------------------------------------------------
Ran 1 test in 17.347s

FAILED (errors=1)
